Workbook
Name cam_thi: 'diem danh hang ngay'!$A$2:$A$4
Name cấm_thi_danh_sách_cấm_thi: 'diem danh hang ngay'!$A$1:$A$4
Name mon_thi: 'diem danh hang ngay'!$E$8:$E$19
Name môn_thi: 'diem danh hang ngay'!$D$1:$D$21
Name mon_thi_hk: 'diem danh hang ngay'!$D$1:$D$19
Name môn_thi_hk: 'diem danh hang ngay'!$D$1:$D$19
Name thay_day: 'diem danh hang ngay'!$C$1:$C$21
Name thay_day_mon: 'diem danh hang ngay'!$D$8:$D$24

Sheet MAU
A1: PHÂN HIỆU HỌC VIỆN KTMM | E1: CỘNG HÒA XÃ HỘI CHỦ NGHĨA VIỆT NAM | K1: PHÂN HIỆU HỌC VIỆN KTMM | P1: CỘNG HÒA XÃ HỘI CHỦ NGHĨA VIỆT NAM
A2: TẠI TP. HỒ CHÍ MINH | E2: Độc lập - Tự do - Hạnh phúc | K2: TẠI TP. HỒ CHÍ MINH | P2: Độc lập - Tự do - Hạnh phúc
A3: BAN KT&ĐBCLĐT | K3: BAN KT&ĐBCLĐT
A5: KẾT QUẢ ĐÁNH GIÁ ĐIỂM QUÁ TRÌNH | K5: KẾT QUẢ ĐIỂM HỌC PHẦN
A6: Học kỳ 2 năm học 2025 - 2026 | K6: =A6 -> Học kỳ 2 năm học 2025 - 2026
A8: Môn thi: | F8: Giảng viên: | H8: =VLOOKUP(A8,'diem danh hang ngay'!$D$1:$E$13,2,0) -> 0 | K8: Môn thi: | P8: Giảng viên : | R8: =VLOOKUP(A8,'diem danh hang ngay'!$D$1:$E$13,2,0) -> 0
A9: Lớp: CHAT4P Khóa: 4 Hệ đào tạo: Sau đại học Chuyên ngành: An toàn thông tin. | K9: =A9 -> Lớp: CHAT4P Khóa: 4 Hệ đào tạo: Sau đại học Chuyên ngành: An toàn thông tin.
A10: Tổng số SV: 26; Số SV dự thi: ; Vắng: ; Có lý do: ; Không lý do: | K10: =A10 -> Tổng số SV: 26; Số SV dự thi: ; Vắng: ; Có lý do: ; Không lý do:
A11: STT | B11: MSSV | C11: Họ Và tên | E11: Điểm TP 1 | F11: Điểm TP 2 | G11: Điểm quá trình | J11: Ghi Chú | K11: STT | L11: MSSV | M11: Họ và tên | O11: Điểm QT | P11: Điểm thi KTHP | Q11: Điểm học phần | T11: Ghi Chú
G12: Bằng số | H12: Bằng chữ | Q12: Bằng số | R12: Bằng chữ
A13: 1 | B13: =VLOOKUP(A13,'danh sach sinh vien'!$A$2:$C$51,2,1) -> CHAT4P001 | C13: =VLOOKUP(A13,'danh sach sinh vien'!$A$2:$C$51,3,1) -> Vũ Thị Diệu Anh | G13: =ROUND(E13*0.7+F13*0.3,1) -> 0 | H13: =VLOOKUP(G13,'diem bang chu'!$J$2:$K$93,2,1) -> Không | K13: 1 | L13: =VLOOKUP(K13,'danh sach sinh vien'!$A$2:$C$51,2,1) -> CHAT4P001 | M13: =VLOOKUP(K13,'danh sach sinh vien'!$A$2:$C$51,3,1) -> Vũ Thị Diệu Anh | O13: =VLOOKUP(K13,$A$13:$G$29,7,1) -> 0 | Q13: =ROUND(O13*0.3+P13*0.7,1) -> 0 | R13: =VLOOKUP(Q13,'diem bang chu'!$J$2:$K$93,2,1) -> Không
A14: =A13+1 -> 2 | B14: =VLOOKUP(A14,'danh sach sinh vien'!$A$2:$C$51,2,1) -> CHAT4P002 | C14: =VLOOKUP(A14,'danh sach sinh vien'!$A$2:$C$51,3,1) -> Nguyễn Tuấn Anh | G14: =ROUND(E14*0.7+F14*0.3,1) -> 0 | H14: =VLOOKUP(G14,'diem bang chu'!$J$2:$K$93,2,1) -> Không | K14: =K13+1 -> 2 | L14: =VLOOKUP(K14,'danh sach sinh vien'!$A$2:$C$51,2,1) -> CHAT4P002 | M14: =VLOOKUP(K14,'danh sach sinh vien'!$A$2:$C$51,3,1) -> Nguyễn Tuấn Anh | O14: =VLOOKUP(K14,$A$13:$G$29,7,1) -> 0 | Q14: =ROUND(O14*0.3+P14*0.7,1) -> 0 | R14: =VLOOKUP(Q14,'diem bang chu'!$J$2:$K$93,2,1) -> Không
A15: =A14+1 -> 3 | B15: =VLOOKUP(A15,'danh sach sinh vien'!$A$2:$C$51,2,1) -> CHAT4P003 | C15: =VLOOKUP(A15,'danh sach sinh vien'!$A$2:$C$51,3,1) -> Diệp Kim Chi | G15: =ROUND(E15*0.7+F15*0.3,1) -> 0 | H15: =VLOOKUP(G15,'diem bang chu'!$J$2:$K$93,2,1) -> Không | K15: =K14+1 -> 3 | L15: =VLOOKUP(K15,'danh sach sinh vien'!$A$2:$C$51,2,1) -> CHAT4P003 | M15: =VLOOKUP(K15,'danh sach sinh vien'!$A$2:$C$51,3,1) -> Diệp Kim Chi | O15: =VLOOKUP(K15,$A$13:$G$29,7,1) -> 0 | Q15: =ROUND(O15*0.3+P15*0.7,1) -> 0 | R15: =VLOOKUP(Q15,'diem bang chu'!$J$2:$K$93,2,1) -> Không
A16: =A15+1 -> 4 | B16: =VLOOKUP(A16,'danh sach sinh vien'!$A$2:$C$51,2,1) -> CHAT4P005 | C16: =VLOOKUP(A16,'danh sach sinh vien'!$A$2:$C$51,3,1) -> Nguyễn Vĩnh Hiển | G16: =ROUND(E16*0.7+F16*0.3,1) -> 0 | H16: =VLOOKUP(G16,'diem bang chu'!$J$2:$K$93,2,1) -> Không | K16: =K15+1 -> 4 | L16: =VLOOKUP(K16,'danh sach sinh vien'!$A$2:$C$51,2,1) -> CHAT4P005 | M16: =VLOOKUP(K16,'danh sach sinh vien'!$A$2:$C$51,3,1) -> Nguyễn Vĩnh Hiển | O16: =VLOOKUP(K16,$A$13:$G$29,7,1) -> 0 | Q16: =ROUND(O16*0.3+P16*0.7,1) -> 0 | R16: =VLOOKUP(Q16,'diem bang chu'!$J$2:$K$93,2,1) -> Không
A17: =A16+1 -> 5 | B17: =VLOOKUP(A17,'danh sach sinh vien'!$A$2:$C$51,2,1) -> CHAT4P006 | C17: =VLOOKUP(A17,'danh sach sinh vien'!$A$2:$C$51,3,1) -> Nguyễn Ngọc Hoài | G17: =ROUND(E17*0.7+F17*0.3,1) -> 0 | H17: =VLOOKUP(G17,'diem bang chu'!$J$2:$K$93,2,1) -> Không | K17: =K16+1 -> 5 | L17: =VLOOKUP(K17,'danh sach sinh vien'!$A$2:$C$51,2,1) -> CHAT4P006 | M17: =VLOOKUP(K17,'danh sach sinh vien'!$A$2:$C$51,3,1) -> Nguyễn Ngọc Hoài | O17: =VLOOKUP(K17,$A$13:$G$29,7,1) -> 0 | Q17: =ROUND(O17*0.3+P17*0.7,1) -> 0 | R17: =VLOOKUP(Q17,'diem bang chu'!$J$2:$K$93,2,1) -> Không
A18: =A17+1 -> 6 | B18: =VLOOKUP(A18,'danh sach sinh vien'!$A$2:$C$51,2,1) -> CHAT4P009 | C18: =VLOOKUP(A18,'danh sach sinh vien'!$A$2:$C$51,3,1) -> Nguyễn Trần Hoàng Long | G18: =ROUND(E18*0.7+F18*0.3,1) -> 0 | H18: =VLOOKUP(G18,'diem bang chu'!$J$2:$K$93,2,1) -> Không | K18: =K17+1 -> 6 | L18: =VLOOKUP(K18,'danh sach sinh vien'!$A$2:$C$51,2,1) -> CHAT4P009 | M18: =VLOOKUP(K18,'danh sach sinh vien'!$A$2:$C$51,3,1) -> Nguyễn Trần Hoàng Long | O18: =VLOOKUP(K18,$A$13:$G$29,7,1) -> 0 | Q18: =ROUND(O18*0.3+P18*0.7,1) -> 0 | R18: =VLOOKUP(Q18,'diem bang chu'!$J$2:$K$93,2,1) -> Không
A19: =A18+1 -> 7 | B19: =VLOOKUP(A19,'danh sach sinh vien'!$A$2:$C$51,2,1) -> CHAT4P010 | C19: =VLOOKUP(A19,'danh sach sinh vien'!$A$2:$C$51,3,1) -> Võ Thông Minh | G19: =ROUND(E19*0.7+F19*0.3,1) -> 0 | H19: =VLOOKUP(G19,'diem bang chu'!$J$2:$K$93,2,1) -> Không | K19: =K18+1 -> 7 | L19: =VLOOKUP(K19,'danh sach sinh vien'!$A$2:$C$51,2,1) -> CHAT4P010 | M19: =VLOOKUP(K19,'danh sach sinh vien'!$A$2:$C$51,3,1) -> Võ Thông Minh | O19: =VLOOKUP(K19,$A$13:$G$29,7,1) -> 0 | Q19: =ROUND(O19*0.3+P19*0.7,1) -> 0 | R19: =VLOOKUP(Q19,'diem bang chu'!$J$2:$K$93,2,1) -> Không
A20: =A19+1 -> 8 | B20: =VLOOKUP(A20,'danh sach sinh vien'!$A$2:$C$51,2,1) -> CHAT4P011 | C20: =VLOOKUP(A20,'danh sach sinh vien'!$A$2:$C$51,3,1) -> Huỳnh Trần Trọng Nghĩa | G20: =ROUND(E20*0.7+F20*0.3,1) -> 0 | H20: =VLOOKUP(G20,'diem bang chu'!$J$2:$K$93,2,1) -> Không | K20: =K19+1 -> 8 | L20: =VLOOKUP(K20,'danh sach sinh vien'!$A$2:$C$51,2,1) -> CHAT4P011 | M20: =VLOOKUP(K20,'danh sach sinh vien'!$A$2:$C$51,3,1) -> Huỳnh Trần Trọng Nghĩa | O20: =VLOOKUP(K20,$A$13:$G$29,7,1) -> 0 | Q20: =ROUND(O20*0.3+P20*0.7,1) -> 0 | R20: =VLOOKUP(Q20,'diem bang chu'!$J$2:$K$93,2,1) -> Không
A21: =A20+1 -> 9 | B21: =VLOOKUP(A21,'danh sach sinh vien'!$A$2:$C$51,2,1) -> CHAT4P012 | C21: =VLOOKUP(A21,'danh sach sinh vien'!$A$2:$C$51,3,1) -> Tăng Triển Nguyên | G21: =ROUND(E21*0.7+F21*0.3,1) -> 0 | H21: =VLOOKUP(G21,'diem bang chu'!$J$2:$K$93,2,1) -> Không | K21: =K20+1 -> 9 | L21: =VLOOKUP(K21,'danh sach sinh vien'!$A$2:$C$51,2,1) -> CHAT4P012 | M21: =VLOOKUP(K21,'danh sach sinh vien'!$A$2:$C$51,3,1) -> Tăng Triển Nguyên | O21: =VLOOKUP(K21,$A$13:$G$29,7,1) -> 0 | Q21: =ROUND(O21*0.3+P21*0.7,1) -> 0 | R21: =VLOOKUP(Q21,'diem bang chu'!$J$2:$K$93,2,1) -> Không
A22: =A21+1 -> 10 | B22: =VLOOKUP(A22,'danh sach sinh vien'!$A$2:$C$51,2,1) -> CHAT4P013 | C22: =VLOOKUP(A22,'danh sach sinh vien'!$A$2:$C$51,3,1) -> Võ Minh Nhật | G22: =ROUND(E22*0.7+F22*0.3,1) -> 0 | H22: =VLOOKUP(G22,'diem bang chu'!$J$2:$K$93,2,1) -> Không | K22: =K21+1 -> 10 | L22: =VLOOKUP(K22,'danh sach sinh vien'!$A$2:$C$51,2,1) -> CHAT4P013 | M22: =VLOOKUP(K22,'danh sach sinh vien'!$A$2:$C$51,3,1) -> Võ Minh Nhật | O22: =VLOOKUP(K22,$A$13:$G$29,7,1) -> 0 | Q22: =ROUND(O22*0.3+P22*0.7,1) -> 0 | R22: =VLOOKUP(Q22,'diem bang chu'!$J$2:$K$93,2,1) -> Không
A23: =A22+1 -> 11 | B23: =VLOOKUP(A23,'danh sach sinh vien'!$A$2:$C$51,2,1) -> CHAT4P014 | C23: =VLOOKUP(A23,'danh sach sinh vien'!$A$2:$C$51,3,1) -> Nguyễn Trường Phú | G23: =ROUND(E23*0.7+F23*0.3,1) -> 0 | H23: =VLOOKUP(G23,'diem bang chu'!$J$2:$K$93,2,1) -> Không | K23: =K22+1 -> 11 | L23: =VLOOKUP(K23,'danh sach sinh vien'!$A$2:$C$51,2,1) -> CHAT4P014 | M23: =VLOOKUP(K23,'danh sach sinh vien'!$A$2:$C$51,3,1) -> Nguyễn Trường Phú | O23: =VLOOKUP(K23,$A$13:$G$29,7,1) -> 0 | Q23: =ROUND(O23*0.3+P23*0.7,1) -> 0 | R23: =VLOOKUP(Q23,'diem bang chu'!$J$2:$K$93,2,1) -> Không
A24: =A23+1 -> 12 | B24: =VLOOKUP(A24,'danh sach sinh vien'!$A$2:$C$51,2,1) -> CHAT4P015 | C24: =VLOOKUP(A24,'danh sach sinh vien'!$A$2:$C$51,3,1) -> Nguyễn Đình Quân | G24: =ROUND(E24*0.7+F24*0.3,1) -> 0 | H24: =VLOOKUP(G24,'diem bang chu'!$J$2:$K$93,2,1) -> Không | K24: =K23+1 -> 12 | L24: =VLOOKUP(K24,'danh sach sinh vien'!$A$2:$C$51,2,1) -> CHAT4P015 | M24: =VLOOKUP(K24,'danh sach sinh vien'!$A$2:$C$51,3,1) -> Nguyễn Đình Quân | O24: =VLOOKUP(K24,$A$13:$G$29,7,1) -> 0 | Q24: =ROUND(O24*0.3+P24*0.7,1) -> 0 | R24: =VLOOKUP(Q24,'diem bang chu'!$J$2:$K$93,2,1) -> Không
A25: =A24+1 -> 13 | B25: =VLOOKUP(A25,'danh sach sinh vien'!$A$2:$C$51,2,1) -> CHAT4P016 | C25: =VLOOKUP(A25,'danh sach sinh vien'!$A$2:$C$51,3,1) -> Nguyễn Ngọc Sơn | G25: =ROUND(E25*0.7+F25*0.3,1) -> 0 | H25: =VLOOKUP(G25,'diem bang chu'!$J$2:$K$93,2,1) -> Không | K25: =K24+1 -> 13 | L25: =VLOOKUP(K25,'danh sach sinh vien'!$A$2:$C$51,2,1) -> CHAT4P016 | M25: =VLOOKUP(K25,'danh sach sinh vien'!$A$2:$C$51,3,1) -> Nguyễn Ngọc Sơn | O25: =VLOOKUP(K25,$A$13:$G$29,7,1) -> 0 | Q25: =ROUND(O25*0.3+P25*0.7,1) -> 0 | R25: =VLOOKUP(Q25,'diem bang chu'!$J$2:$K$93,2,1) -> Không
... A29: =A28+1 -> 17 | B29: =VLOOKUP(A29,'danh sach sinh vien'!$A$2:$C$51,2,1) -> CHAT12234 | C29: =VLOOKUP(A29,'danh sach sinh vien'!$A$2:$C$51,3,1) -> Đoàn Quang Phúc | G29: =ROUND(E29*0.7+F29*0.3,1) -> 0 | H29: =VLOOKUP(G29,'diem bang chu'!$J$2:$K$93,2,1) -> Không | K29: =K28+1 -> 17 | L29: =VLOOKUP(K29,'danh sach sinh vien'!$A$2:$C$51,2,1) -> CHAT12234 | M29: =VLOOKUP(K29,'danh sach sinh vien'!$A$2:$C$51,3,1) -> Đoàn Quang Phúc | O29: =VLOOKUP(K29,$A$13:$G$29,7,1) -> 0 | Q29: =ROUND(O29*0.3+P29*0.7,1) -> 0 | R29: =VLOOKUP(Q29,'diem bang chu'!$J$2:$K$93,2,1) -> Không
G30: TP. HCM, Ngày tháng năm 2026 | P30: TP.Hồ Chí Minh, Ngày tháng năm 2026
A31: Giảng viên chấm thi | D31: Phụ trách khoa | G31: Ban KT& ĐBCLĐT | K31: CÁN BỘ CHẤM THI 1 | N31: CÁN BỘ CHẤM THI 2 | P31: BAN KT&ĐBCLĐT
A32: (Ký, ghi rõ họ tên) | D32: (Ký, ghi rõ họ tên) | G32: (Ký, ghi rõ họ tên) | K32: (Ký, ghi rõ họ tên) | N32: (Ký, ghi rõ họ tên) | P32: (Ký, ghi rõ họ tên)
G38: Nguyễn Văn Dương
A40: PHÂN HIỆU HỌC VIỆN KTMM | E40: CỘNG HÒA XÃ HỘI CHỦ NGHĨA VIỆT NAM
A41: BAN KT&ĐBCLĐT | E41: Độc lập - Tự do - Hạnh phúc
A44: BIÊN BẢN
A45: BÀN GIAO BÀI THI KÈM THEO DANH SÁCH SINH VIÊN DỰ THI
A47: Học kỳ 2; Năm học 2025 - 2026
A48: Môn thi: | F48: Giảng viên : | H48: =VLOOKUP(A48,'diem danh hang ngay'!$D$1:$E$13,2,0) -> 0
A49: =A9 -> Lớp: CHAT4P Khóa: 4 Hệ đào tạo: Sau đại học Chuyên ngành: An toàn thông tin.
A50: Tổng số thí sinh: 17; Thí sinh dự thi:.............; Vắng:..........; Có lý do:.........; Không lý do:........
A51: Thi lần thứ: Nhất; Hình thức thi:....................................; Ngày thi:........./.........../2026; Phòng thi:................
A52: STT | B52: MSSV | C52: Họ Và tên | E52: SBD | F52: ĐỀ SỐ | G52: SỐ TGT | H52: KÝ TÊN | J52: GHI CHÚ
A54: 1 | B54: =VLOOKUP(A54,'danh sach sinh vien'!$A$2:$C$51,2,1) -> CHAT4P001 | C54: =VLOOKUP(A54,'danh sach sinh vien'!$A$2:$C$51,3,1) -> Vũ Thị Diệu Anh | E54: 1
A55: 2 | B55: =VLOOKUP(A55,'danh sach sinh vien'!$A$2:$C$51,2,1) -> CHAT4P002 | C55: =VLOOKUP(A55,'danh sach sinh vien'!$A$2:$C$51,3,1) -> Nguyễn Tuấn Anh | E55: 2
...

Sheet diem bang chu
J1: bang diem bang chu
J2: 0 | K2: Không
J3: 1 | K3: Một
J4: 1.1 | K4: Một phẩy một
J5: 1.2 | K5: Một phẩy hai
J6: 1.3 | K6: Một phẩy ba
J7: 1.4 | K7: Một phẩy bốn
J8: 1.5 | K8: Một phẩy năm
J9: 1.6 | K9: Một phẩy sáu
J10: 1.7 | K10: Một phẩy bảy
J11: 1.8 | K11: Một phẩy tám
J12: 1.9 | K12: Một phẩy chín
J13: 2 | K13: Hai
... J93: 10 | K93: Mười

Sheet diem danh hang ngay
A1: cấm thi danh sách cấm thi | C1: TT | D1: MÔN THI | E1: HỌ TÊN GIẢNG VIÊN
A2: cấm thi nghỉ quá 25% | C2: 1 | D2: Môn thi:
A3: điểm giữa ký <5 | C3: 2 | D3: Môn thi:
A4: Nghỉ 100% | C4: 3
C5: 4
C6: 5

Sheet danh sach sinh vien
A1: TT | B1: MSHV | C1: Họ và tên | D1: Nhóm | E1: Tên nhóm | F1: Vai trò | G1: Ngành | H1: Email | I1: Đơn vị công tác | J1: Buổi bảo vệ
A2: 1 | B2: CHAT4P001 | C2: Vũ Thị Diệu Anh | D2: Nhóm 4 | E2: CAP | F2: Trưởng nhóm | G2: CNTT | H2: vuthidieuanh1511@gmail.com | I2: TMA Solution (QA) | J2: Buổi S08 | K2: Đang học
A3: =A2+1 -> 2 | B3: CHAT4P002 | C3: Nguyễn Tuấn Anh | D3: Miễn | E3: Miễn học phần | F3: Được miễn môn | J3: Miễn thi | K3: Miễn môn học
A4: =A3+1 -> 3 | B4: CHAT4P003 | C4: Diệp Kim Chi | D4: Nhóm 4 | E4: CAP | F4: Thành viên | G4: CNTT | H4: chidiep23122003@gmail.com | I4: Digityze Asia | J4: Buổi S08 | K4: Đang học
A5: =A4+1 -> 4 | B5: CHAT4P005 | C5: Nguyễn Vĩnh Hiển | D5: Nhóm 2 | E5: RootCA | F5: Trưởng nhóm | G5: CNTT | H5: hienhungvuong@gmail.com | I5: Dược Imexpharm | J5: Buổi S07 | K5: Đang học
A6: =A5+1 -> 5 | B6: CHAT4P006 | C6: Nguyễn Ngọc Hoài | D6: Nhóm 1 | E6: VAULT | F6: Trưởng nhóm | G6: ATTT | H6: hoainnuit@gmail.com | I6: AgileOps (DevOps) | J6: Buổi S07 | K6: Đang học
A7: =A6+1 -> 6 | B7: CHAT4P009 | C7: Nguyễn Trần Hoàng Long | D7: Nhóm 1 | E7: VAULT | F7: Thành viên | G7: ATTT | H7: longhoangnguyen12092@gmail.com | I7: An ninh mạng THD | J7: Buổi S07 | K7: Đang học
A8: =A7+1 -> 7 | B8: CHAT4P010 | C8: Võ Thông Minh | D8: Nhóm 3 | E8: TMN Root of Trust | F8: Trưởng nhóm | G8: ATTT | H8: minh8356@gmail.com | I8: Ngân hàng Nam Á | J8: Buổi S08 | K8: Đang học
A9: =A8+1 -> 8 | B9: CHAT4P011 | C9: Huỳnh Trần Trọng Nghĩa | D9: Miễn | E9: Miễn học phần | F9: Được miễn môn | J9: Miễn thi | K9: Miễn môn học
A10: =A9+1 -> 9 | B10: CHAT4P012 | C10: Tăng Triển Nguyên | D10: Nhóm 3 | E10: TMN Root of Trust | F10: Thành viên (Lớp trưởng) | G10: CNTT | H10: triennguyen1911@gmail.com | I10: Getz Pharma | J10: Buổi S08 | K10: Đang học
A11: =A10+1 -> 10 | B11: CHAT4P013 | C11: Võ Minh Nhật | D11: Nhóm 5 | E11: TYN | F11: Trưởng nhóm | G11: CNTT | H11: vonhat010@gmail.com | I11: Đi học | J11: Buổi S09 | K11: Đang học
A12: =A11+1 -> 11 | B12: CHAT4P014 | C12: Nguyễn Trường Phú | D12: Nhóm 2 | E12: RootCA | F12: Thành viên | G12: CNTT | H12: phu.nguyen@owasp.org | I12: Cố vấn an ninh mạng (OWASP) | J12: Buổi S07 | K12: Đang học
A13: =A12+1 -> 12 | B13: CHAT4P015 | C13: Nguyễn Đình Quân | D13: Nhóm 1 | E13: VAULT | F13: Thành viên | G13: ATTT | H13: nguyendinhquan135@gmail.com | I13: ĐH Nguyễn Tất Thành | J13: Buổi S07 | K13: Đang học
A14: =A13+1 -> 13 | B14: CHAT4P016 | C14: Nguyễn Ngọc Sơn | D14: Nhóm 2 | E14: RootCA | F14: Thành viên | G14: CNTT | H14: sonnn.tech@gmail.com | I14: VinSmart Future | J14: Buổi S07 | K14: Đang học
A15: =A14+1 -> 14 | B15: CHAT4P017 | C15: Hồ Quốc Thái | D15: Nhóm 5 | E15: TYN | F15: Thành viên | G15: CNTT | H15: thaisonnam@gmail.com | I15: Hitachi Digital Service | J15: Buổi S09 | K15: Đang học
A16: =A15+1 -> 15 | B16: CHAT4P018 | C16: Trần Minh Triết | D16: Nhóm 3 | E16: TMN Root of Trust | F16: Thành viên | G16: ATTT | H16: triettran030103@gmail.com | I16: OPSWAT Việt Nam | J16: Buổi S08 | K16: Đang học
A17: =A16+1 -> 16 | B17: CHAT4P020 | C17: Nguyễn Công Ý | D17: Nhóm 5 | E17: TYN | F17: Thành viên | G17: CNTT | H17: nguyencongy0493@gmail.com | I17: Ngân hàng ACB | J17: Buổi S09 | K17: Đang học
A18: =A17+1 -> 17 | B18: CHAT12234 | C18: Đoàn Quang Phúc | D18: Nhóm 4 | E18: CAP | F18: Thành viên | G18: Tin học ứng dụng | H18: dqphuc011@gmail.com | I18: Trung tâm 286 - BTL 86 | J18: Buổi S08 | K18: Đang học
